<mujoco model="00_all_20240516.SLDASM">
    <compiler angle="radian" meshdir="./Allmesh/robot_meshes/"/>
    <size njmax="500" nconmax="100" />
    <option gravity="0 0 -9.81" timestep="0.01"/>
    <asset>
        <mesh name="base_link" file="base_link_new.STL" />
        <mesh name="left_steering_link" file="left_steering_link.STL" />
        <mesh name="right_steering_link" file="right_steering_link.STL" />
        <mesh name="front_left_wheel_Link" file="front_left_wheel_Link.STL" />
        <mesh name="front_right_wheel_Link" file="front_right_wheel_Link.STL" />
        <mesh name="rear_left_wheel_Link" file="rear_left_wheel_Link.STL" />
        <mesh name="rear_right_wheel_Link" file="rear_right_wheel_Link.STL" />
        <mesh name="handle_Link" file="handle_Link.STL" />
        <mesh name="plane_Link" file="plane_Link.STL" />
        <texture builtin="checker" height="100" name="texplane" rgb1="1 1 1" rgb2="0.8 0.8 0.8" type="2d" width="100"/>
        <material name="MatPlane" reflectance="0.5" shininess="1" specular="1" texrepeat="60 60" texture="texplane"/>
    </asset>
    <worldbody>
    <geom conaffinity="1" condim="3" material="MatPlane" friction=".5 0.005 0.0001" name="floor" pos="0 0 0" rgba="0.8 0.9 0.8 1" size="40 40 40" type="plane"/>
    
    <body name="base" pos="0 0 0" quat="1 1 0 0">
      <freejoint/>
        <geom type="mesh" contype="1" conaffinity="0" group="1" rgba="0.239216 0.317647 0.227451 1" mesh="base_link" density="1000"/>
        <body name="right_steering_link" pos="0.3125 0.1182 0.1792" quat="0.707105 0.707108 0 0">
            <inertial pos="6.8053e-08 0.0481378 -0.0356571" quat="0.626113 0.779732 5.58039e-06 -2.89094e-06" mass="0.176526" diaginertia="0.000398379 0.000350283 7.39585e-05" />
            <joint name="right_steering_joint" pos="0 0 0" axis="0 0 -1" limited="true" range="-0.5 0.5"/>
            <geom type="mesh" contype="1" conaffinity="0" group="1" rgba="0.584314 0.584314 0.584314 1" mesh="right_steering_link" />
            <body name="front_right_wheel_link" pos="0 0.1058 -0.0288">
                <inertial pos="0 2.5429e-06 0" quat="0.438658 0.554598 0.554598 0.438658" mass="4.37453" diaginertia="0.0565948 0.0315356 0.0315351" />
                <joint name="front_right_wheel_joint" pos="0 0 0" axis="0 1 0" />
                <geom type="mesh" contype="1" conaffinity="0" group="1" rgba="0.0980392 0.0980392 0.0980392 1" mesh="front_right_wheel_Link" />
            </body>
        </body>
        <body name="left_steering_link" pos="0.3125 0.1182 -0.1792" quat="0.707105 0.707108 0 0">
            <inertial pos="3.48168e-07 -0.0481376 -0.0356571" quat="0.779732 0.626113 -6.81975e-06 3.27842e-06" mass="0.176527" diaginertia="0.000398382 0.000350288 7.39596e-05" />
            <joint name="left_steering_joint" pos="0 0 0" axis="0 0 -1" limited="true" range="-0.5 0.5" />
            <geom type="mesh" contype="1" conaffinity="0" group="1" rgba="0.584314 0.584314 0.584314 1" mesh="left_steering_link" />
            <body name="front_left_wheel_link" pos="0 -0.1058 -0.0288" quat="-3.67321e-06 1 0 0">
                <inertial pos="0 2.5429e-06 0" quat="0.438658 0.554598 0.554598 0.438658" mass="4.37453" diaginertia="0.0565948 0.0315356 0.0315351" />
                <joint name="front_left_wheel_joint" pos="0 0 0" axis="0 1 0" />
                <geom type="mesh" contype="1" conaffinity="0" group="1" rgba="0.0980392 0.0980392 0.0980392 1" mesh="front_left_wheel_Link" />
            </body>
        </body>
        <body name="rear_left_wheel_Link" pos="-0.3125 0.147 -0.285" quat="0.707105 -0.707108 0 0">
            <inertial pos="0 2.54252e-06 0" quat="0.494999 0.504951 0.504951 0.494999" mass="4.37454" diaginertia="0.0565948 0.0315357 0.0315351" />
            <joint name="rear_left_wheel_joint" pos="0 0 0" axis="0 1 0" />
            <geom type="mesh" contype="1" conaffinity="0" group="1" rgba="0.0941176 0.0941176 0.0941176 1" mesh="rear_left_wheel_Link" />
        </body>
        <body name="rear_right_wheel_Link" pos="-0.3125 0.147 0.285" quat="0.707105 0.707108 0 0">
            <inertial pos="0 2.54252e-06 0" quat="0.494999 0.504951 0.504951 0.494999" mass="4.37454" diaginertia="0.0565948 0.0315357 0.0315351" />
            <joint name="rear_right_wheel_joint" pos="0 0 0" axis="0 1 0" />
            <geom type="mesh" contype="1" conaffinity="0" group="1" rgba="0.0941176 0.0941176 0.0941176 1" mesh="rear_right_wheel_Link" />
        </body>
        <body name="handle_Link" pos="-0.4345 0.853 0.406" quat="1.34924e-11 3.67321e-06 -1 -3.67321e-06">
            <inertial pos="-0.234705 -0.0584311 0.0186125" quat="0.505098 0.500862 -0.499441 0.494542" mass="0.475034" diaginertia="0.00171862 0.00125326 0.00063586" />
            <joint name="handle_joint" pos="0 0 0" axis="0 1 0" type="slide" limited="true" range="-0.63 0" />
            <geom type="mesh" contype="1" conaffinity="0" group="1" rgba="0.305882 0.32549 0.352941 1" mesh="handle_Link" />
            <body name="plane_Link" pos="-0.4345 -0.2 0.036" quat="1.34924e-11 3.67321e-06 -1 -3.67321e-06">
                <inertial pos="-0.180014 0.759611 0.384771" quat="-0.00113978 0.707107 -0.000387157 0.707106" mass="0.470939" diaginertia="0.00535856 0.00360992 0.0017562" />
                <joint name="plane_joint" pos="0 0 0" axis="1 0 0" limited="true" range="0 1.6" />
                <geom pos="0 -0.653 -0.37" type="mesh" contype="1" conaffinity="0" group="1" rgba="0.305882 0.32549 0.352941 1" mesh="plane_Link" />
            </body>
        </body>
        <body name="weight_link" pos="0.3 0.5 0" quat="0 0 0 1">
            <geom name="weight" size="0.05 0.05 0.05" pos="0 0 0" type="box" rgba="0.8 0.8 0.8 1" density="1500"/>
        </body>
        
    </body>
    </worldbody>

  <actuator>
    <motor name="rear_left_wheel_joint" joint="rear_left_wheel_joint" ctrllimited="true" ctrlrange="-100 100" forcelimited="true" forcerange="-100 100"/>
    <motor name="rear_right_wheel_joint" joint="rear_right_wheel_joint" gear="-1" ctrllimited="true" ctrlrange="-100 100" forcelimited="true" forcerange="-100 100"/>
    <position name="left_steering_joint" joint= "left_steering_joint" kp="1000" kv='10' ctrllimited="true" forcelimited="true" forcerange="-200 200" ctrlrange="-0.5 0.5"/>
    <position name="right_steering_joint" joint= "right_steering_joint"  kp="1000" kv='10' ctrllimited="true" forcelimited="true" forcerange="-200 200" ctrlrange="-0.5 0.5"/>
    <motor name="handle_joint"  joint="handle_joint" ctrllimited="false"  forcelimited="true" forcerange="-500 500"/>
    <motor name="plane_joint"  joint="plane_joint"   ctrllimited="false" forcelimited="true" forcerange="-500 500"/>
  </actuator>


</mujoco>
