<mujoco model="robomaster_s1">
  <compiler angle="radian" meshdir="./Allmesh/robot_meshes/"/>

  <asset>
    <mesh name="armor" file="armor.stl"/>
    <mesh name="battery" file="battery.stl"/>
    <mesh name="battery_pin_left" file="battery_pin_left.stl"/>
    <mesh name="battery_pin_right" file="battery_pin_right.stl"/>
    <mesh name="chassis" file="chassis.stl"/>
    <mesh name="controller" file="controller.stl"/>
    <mesh name="controller_cover" file="controller_cover.stl"/>
    <mesh name="base_collision" file="base_collision.stl"/>
    <mesh name="hit_sensor" file="hit_sensor.stl"/>
    <mesh name="led" file="led.stl"/>
    <mesh name="wheel" file="wheel.stl"/>
    <mesh name="wheel1" file="wheel.stl" scale="1 -1 1"/>
    <mesh name="blaster_bug" file="blaster_bug.stl" scale="0.7949 0.7949 0.7949"/>
    <mesh name="blaster_gun" file="blaster_gun.stl"/>
    <mesh name="blaster_magazin" file="blaster_magazin.stl"/>
    <mesh name="blaster_top" file="blaster_top.stl"/>
    <mesh name="blaster_gun_collision" file="blaster_gun_collision.stl"/>
    <mesh name="blaster_magazin_collision" file="blaster_magazin_collision.stl"/>
    <mesh name="blaster_top_collision" file="blaster_top_collision.stl"/>
    <mesh name="gimbal_base" file="gimbal_base.stl"/>
    <mesh name="gimbal_base_collision" file="gimbal_base_collision.stl"/>
    <mesh name="gimbal_left_led" file="gimbal_left_led.stl"/>
    <mesh name="gimbal_left_led_0" file="gimbal_left_led_0.stl"/>
    <mesh name="gimbal_left_led_1" file="gimbal_left_led_1.stl"/>
    <mesh name="gimbal_left_led_2" file="gimbal_left_led_2.stl"/>
    <mesh name="gimbal_left_led_3" file="gimbal_left_led_3.stl"/>
    <mesh name="gimbal_left_led_4" file="gimbal_left_led_4.stl"/>
    <mesh name="gimbal_left_led_5" file="gimbal_left_led_5.stl"/>
    <mesh name="gimbal_left_led_6" file="gimbal_left_led_6.stl"/>
    <mesh name="gimbal_left_led_7" file="gimbal_left_led_7.stl"/>
    <mesh name="gimbal_right_led_0" file="gimbal_right_led_0.stl"/>
    <mesh name="gimbal_right_led_1" file="gimbal_right_led_1.stl"/>
    <mesh name="gimbal_right_led_2" file="gimbal_right_led_2.stl"/>
    <mesh name="gimbal_right_led_3" file="gimbal_right_led_3.stl"/>
    <mesh name="gimbal_right_led_4" file="gimbal_right_led_4.stl"/>
    <mesh name="gimbal_right_led_5" file="gimbal_right_led_5.stl"/>
    <mesh name="gimbal_right_led_6" file="gimbal_right_led_6.stl"/>
    <mesh name="gimbal_right_led7" file="gimbal_right_led7.stl"/>
    <mesh name="gimbal" file="gimbal.stl"/>
    <mesh name="gimbal_left_armor" file="gimbal_left_armor.stl"/>
    <mesh name="gimbal_right_armor" file="gimbal_right_armor.stl"/>
    <mesh name="gimbal_side" file="gimbal_side.stl"/>
    <mesh name="gimbal_collision" file="gimbal_collision.stl"/>
    <mesh name="speaker" file="speaker.stl"/>
    <mesh name="speaker_collision" file="speaker_collision.stl"/>
    <mesh name="camera" file="camera.stl" scale="1 1 1"/>
    <mesh name="intelligent_controller" file="intelligent_controller.stl"/>
    <mesh name="wifi_antenna_left" file="wifi_antenna_left.stl"/>
    <mesh name="wifi_antenna_right" file="wifi_antenna_right.stl"/>
    <texture builtin="checker" height="100" name="texplane" rgb1="1 1 1" rgb2="0.8 0.8 0.8" type="2d" width="100"/>
    <material name="MatPlane" reflectance="0.5" shininess="1" specular="1" texrepeat="60 60" texture="texplane"/>
  </asset>

  <worldbody>
  <geom conaffinity="1" condim="3" material="MatPlane" friction=".5 0.005 0.0001" name="floor" pos="0 0 0" rgba="0.8 0.9 0.8 1" size="40 40 40" type="plane"/>
  <body name="base" pos="0 0 0" quat="-1 0 0 1">
    <geom name="armor" pos="-0.0064553 -0.078141 0.0639377" quat="1 0 0 0" type="mesh" contype="0" conaffinity="0" group="1" density="0" rgba="0.227713 0.227713 0.227713 0.8" mesh="armor"/>
    <geom name="battery" pos="-0.130336 -0.0018702 0.0520677" quat="1 0 0 0" type="mesh" contype="0" conaffinity="0" group="1" density="0" rgba="0.0281746 0.0281746 0.0281746 1" mesh="battery"/>
    <geom name="battery_pin_left" pos="-0.115891 0.066115 0.0871743" quat="1 0 0 0" type="mesh" contype="0" conaffinity="0" group="1" density="0" rgba="0.0281746 0.0281746 0.0281746 1" mesh="battery_pin_left"/>
    <geom name="battery_pin_right" pos="-0.115891 -0.0658844 0.0871743" quat="1 0 0 0" type="mesh" contype="0" conaffinity="0" group="1" density="0" rgba="0.0281746 0.0281746 0.0281746 1" mesh="battery_pin_right"/>
    <geom name="chassis" pos="-0.0059039 0.0004154 0.0874455" quat="1 0 0 0" type="mesh" contype="0" conaffinity="0" group="1" density="0" rgba="0.0981132 0.0981132 0.0981132 1" mesh="chassis"/>
    <geom name="controller" pos="-0.114229 -0.0006716 0.087325" quat="1 0 0 0" type="mesh" contype="0" conaffinity="0" group="1" density="0" rgba="0.0281746 0.0281746 0.0281746 1" mesh="controller"/>
    <geom name="controller_cover" pos="-0.0787757 -0.002522 0.106733" quat="1 0 0 0" type="mesh" contype="0" conaffinity="0" group="1" density="0" rgba="0.254832 0.254832 0.254832 0.3" mesh="controller_cover"/>
    <geom name="base_collision" pos="-0.0058789 -0.0001128 0.0640807" quat="1 0 0 0" type="mesh" rgba="0.254832 0.254832 0.254832 0.3" mesh="base_collision"/>
    <geom name="front_hit_sensor" pos="0.156999 -0.0004276 0.0779362" quat="1 0 0 0" type="mesh" contype="0" conaffinity="0" group="1" density="0" rgba="0.169785 0.169785 0.169785 1" mesh="hit_sensor"/>
    <geom name="front_led" pos="0.165741 -0.0017117 0.0779737" quat="1 0 0 0" type="mesh" contype="0" conaffinity="0" group="1" density="0" rgba="0 0.777358 0.777358 1" mesh="led"/>
    <geom name="left_hit_sensor" pos="-0.0024413 0.0886932 0.0644841" quat="0.707107 0 0 0.707107" type="mesh" contype="0" conaffinity="0" group="1" density="0" rgba="0.169785 0.169785 0.169785 1" mesh="hit_sensor"/>
    <geom name="left_led" pos="-0.0011572 0.097436 0.0645216" quat="0.707107 0 0 0.707107" type="mesh" contype="0" conaffinity="0" group="1" density="0" rgba="0 0.777358 0.777358 1" mesh="led"/>
    <geom name="rear_hit_sensor" pos="-0.158183 -0.0027864 0.0650168" quat="0 0 0 1" type="mesh" contype="0" conaffinity="0" group="1" density="0" rgba="0.169785 0.169785 0.169785 1" mesh="hit_sensor"/>
    <geom name="rear_led" pos="-0.166926 -0.0015023 0.0650543" quat="0 0 0 1" type="mesh" contype="0" conaffinity="0" group="1" density="0" rgba="0 0.777358 0.777358 1" mesh="led"/>
    <geom name="right_hit_sensor" pos="-0.0024413 -0.0886932 0.0644841" quat="0.707107 0 0 -0.707107" type="mesh" contype="0" conaffinity="0" group="1" density="0" rgba="0.169785 0.169785 0.169785 1" mesh="hit_sensor"/>
    <geom name="right_led" pos="-0.0037254 -0.097436 0.0645216" quat="0.707107 0 0 -0.707107" type="mesh" contype="0" conaffinity="0" group="1" density="0" rgba="0 0.777358 0.777358 1" mesh="led"/>
    <geom name="gimbal_base" pos="-0.002 0 0.118" quat="1 0 0 0" type="mesh" contype="0" conaffinity="0" group="1" density="0" rgba="0.12595 0.12595 0.12595 1" mesh="gimbal_base"/>
    <geom name="gimbal_base_collision" pos="-0.00316 -0.00092 0.11557" quat="1 0 0 0" type="mesh" rgba="0.12595 0.12595 0.12595 1" mesh="gimbal_base_collision"/>
    <geom name="gimbal" pos="-0.00202 -0.001 0.15169" quat="1 0 0 0" type="mesh" contype="0" conaffinity="0" group="1" density="0" rgba="0.12595 0.12595 0.12595 1" mesh="gimbal"/>
    <geom name="gimbal_left_armor" pos="-0.00672 0.06418 0.18922" quat="1 0 0 0" type="mesh" contype="0" conaffinity="0" group="1" density="0" rgba="0.06401 0.06401 0.06401 1" mesh="gimbal_left_armor"/>
    <geom name="gimbal_right_armor" pos="-0.00727 -0.06277 0.19114" quat="1 0 0 0" type="mesh" contype="0" conaffinity="0" group="1" density="0" rgba="0.06401 0.06401 0.06401 1" mesh="gimbal_right_armor"/>
    <geom name="gimbal_side" pos="-0.00227 0.00034 0.20555" quat="1 0 0 0" type="mesh" contype="0" conaffinity="0" group="1" density="0" rgba="0.01758 0.01758 0.01758 1" mesh="gimbal_side"/>
    <geom name="gimbal_collision" pos="-0.01847 -0.05644 0.17229" type="mesh" rgba="0.01758 0.01758 0.01758 1" mesh="gimbal_collision"/>
    <geom name="blaster_bug" pos="-0.00198 -0.03893 0.21319" quat="1 0 0 0" type="mesh" contype="0" conaffinity="0" group="1" density="0" rgba="0.06401 0.06401 0.06401 1" mesh="blaster_bug"/>
    <geom name="blaster_gun" pos="0.03669 0.0036 0.19484" quat="1 0 0 0" type="mesh" contype="0" conaffinity="0" group="1" density="0" rgba="0.06401 0.06401 0.06401 1" mesh="blaster_gun"/>
    <geom name="blaster_magazin" pos="-0.02258 0.00035 0.23421" quat="1 0 0 0" type="mesh" contype="0" conaffinity="0" group="1" density="0" rgba="0.76578 0.76578 0.76578 1" mesh="blaster_magazin"/>
    <geom name="blaster_top" pos="-0.00087 0.00116 0.22258" quat="1 0 0 0" type="mesh" contype="0" conaffinity="0" group="1" density="0" rgba="0.47861 0.47861 0.47861 1" mesh="blaster_top"/>
    <geom name="blaster_gun_collision" pos="0.03448 0.00169 0.19531" quat="1 0 0 0" type="mesh" rgba="0.47861 0.47861 0.47861 1" mesh="blaster_gun_collision"/>
    <geom name="blaster_magazin_collision" pos="-0.02395 0.00035 0.23466" quat="1 0 0 0" type="mesh" rgba="0.47861 0.47861 0.47861 1" mesh="blaster_magazin_collision"/>
    <geom name="blaster_top_collision" pos="0.0012 0.00114 0.21689" quat="1 0 0 0" type="mesh" rgba="0.47861 0.47861 0.47861 1" mesh="blaster_top_collision"/>
    <geom name="speaker" pos="-0.01528 0.00725 0.14438" quat="1 0 0 0" type="mesh" contype="0" conaffinity="0" group="1" density="0" mesh="speaker"/>
    <geom name="speaker_collision" pos="-0.01936 0.00369 0.14367" quat="1 0 0 0" type="mesh" mesh="speaker_collision"/>
    <geom name="camera" pos="0.0701244 0.00034 0.236979" quat="0.996195 0 -0.0871539 0" type="mesh" contype="0" conaffinity="0" group="1" density="0" rgba="0.0281746 0.028 0.0281746 1" mesh="camera"/>
    <geom name="intelligent_controller" pos="-0.02927 0.00034 0.266027" quat="1 0 0 0" type="mesh" contype="0" conaffinity="0" group="1" density="0" rgba="0.8 0.8 0.8 1" mesh="intelligent_controller"/>
    <geom name="wifi_antenna_left" pos="-0.0439805 0.0348187 0.278837" quat="1 0 0 0" type="mesh" contype="0" conaffinity="0" group="1" density="0" rgba="0.8 0.8 0.8 1" mesh="wifi_antenna_left"/>
    <geom name="wifi_antenna_right" pos="-0.0439825 -0.0347998 0.27975" quat="1 0 0 0" type="mesh" contype="0" conaffinity="0" group="1" density="0" rgba="0.8 0.8 0.8 1" mesh="wifi_antenna_right"/>
    <geom name="top" size="0.0544865 0.0295514 0.0114575" pos="-0.0061042 0.0003198 0.264166" type="box" rgba="0.8 0.8 0.8 1"/>
    <geom name="gimbal_left_led" pos="-0.02631 0.07079 0.22176" quat="1 0 0 0" type="mesh" contype="0" conaffinity="0" group="1" density="0" rgba="0.78118 0.78118 0.78118 1" mesh="gimbal_left_led"/>
    <geom name="gimbal_left_led_0" pos="-0.02533 0.07079 0.18827" quat="1 0 0 0" type="mesh" contype="0" conaffinity="0" group="1" density="0" rgba="0.78118 0.78118 0.78118 1" mesh="gimbal_left_led_0"/>
    <geom name="gimbal_left_led_1" pos="-0.01005 0.07079 0.17784" quat="1 0 0 0" type="mesh" contype="0" conaffinity="0" group="1" density="0" rgba="0.78118 0.78118 0.78118 1" mesh="gimbal_left_led_1"/>
    <geom name="gimbal_left_led_2" pos="0.00859 0.07079 0.17874" quat="1 0 0 0" type="mesh" contype="0" conaffinity="0" group="1" density="0" rgba="0.78118 0.78118 0.78118 1" mesh="gimbal_left_led_2"/>
    <geom name="gimbal_left_led_3" pos="0.0226 0.07079 0.1906" quat="1 0 0 0" type="mesh" contype="0" conaffinity="0" group="1" density="0" rgba="0.78118 0.78118 0.78118 1" mesh="gimbal_left_led_3"/>
    <geom name="gimbal_left_led_4" pos="0.02121 0.07075 0.22233" quat="1 0 0 0" type="mesh" contype="0" conaffinity="0" group="1" density="0" rgba="0.78118 0.78118 0.78118 1" mesh="gimbal_left_led_4"/>
    <geom name="gimbal_left_led_5" pos="0.00706 0.07079 0.23264" quat="1 0 0 0" type="mesh" contype="0" conaffinity="0" group="1" density="0" rgba="0.78118 0.78118 0.78118 1" mesh="gimbal_left_led_5"/>
    <geom name="gimbal_left_led_6" pos="-0.01119 0.0708 0.2327" quat="1 0 0 0" type="mesh" contype="0" conaffinity="0" group="1" density="0" rgba="0.78118 0.78118 0.78118 1" mesh="gimbal_left_led_6"/>
    <geom name="gimbal_left_led_7" pos="-0.02631 0.07079 0.22176" quat="1 0 0 0" type="mesh" contype="0" conaffinity="0" group="1" density="0" rgba="0.78118 0.78118 0.78118 1" mesh="gimbal_left_led_7"/>
    <geom name="gimbal_right_led_0" pos="-0.02532 -0.0695 0.18827" quat="1 0 0 0" type="mesh" contype="0" conaffinity="0" group="1" density="0" rgba="0.78118 0.78118 0.78118 1" mesh="gimbal_right_led_0"/>
    <geom name="gimbal_right_led_1" pos="-0.01005 -0.06952 0.17783" quat="1 0 0 0" type="mesh" contype="0" conaffinity="0" group="1" density="0" rgba="0.78118 0.78118 0.78118 1" mesh="gimbal_right_led_1"/>
    <geom name="gimbal_right_led_2" pos="0.00859 -0.06952 0.17874" quat="1 0 0 0" type="mesh" contype="0" conaffinity="0" group="1" density="0" rgba="0.78118 0.78118 0.78118 1" mesh="gimbal_right_led_2"/>
    <geom name="gimbal_right_led_3" pos="0.0226 -0.06952 0.1906" type="mesh" contype="0" conaffinity="0" group="1" density="0" rgba="0.78118 0.78118 0.78118 1" mesh="gimbal_right_led_3"/>
    <geom name="gimbal_right_led_4" pos="0.02122 -0.06924 0.22232" quat="1 0 0 0" type="mesh" contype="0" conaffinity="0" group="1" density="0" rgba="0.78118 0.78118 0.78118 1" mesh="gimbal_right_led_4"/>
    <geom name="gimbal_right_led_5" pos="0.00706 -0.06933 0.2327" quat="1 0 0 0" type="mesh" contype="0" conaffinity="0" group="1" density="0" rgba="0.78118 0.78118 0.78118 1" mesh="gimbal_right_led_5"/>
    <geom name="gimbal_right_led_6" pos="-0.01125 -0.06933 0.23267" quat="1 0 0 0" type="mesh" contype="0" conaffinity="0" group="1" density="0" rgba="0.78118 0.78118 0.78118 1" mesh="gimbal_right_led_6"/>
    <geom name="gimbal_right_led_7" pos="-0.02631 -0.06933 0.22176" type="mesh" contype="0" conaffinity="0" group="1" density="0" rgba="0.78118 0.78118 0.78118 1" mesh="gimbal_right_led7"/>
    <freejoint/>
    <body name="front_left_wheel_link" pos="0.1 0.1 0.05">
      <inertial pos="-0.0002104 5.31e-05 -0.0004148" mass="0.162" diaginertia="0.0002 0.00012 0.00012"/>
      <joint name="front_left_wheel_joint" pos="0 0 0" axis="0 1 0"/>
      <geom name="front_left_wheel_bolt" size="0.007 0.0005" pos="0 0.0145 0" quat="0.707107 0.707107 0 0" type="cylinder" contype="0" conaffinity="0" group="1" density="0" rgba="0.45 0.15 0 1"/>
      <geom name="front_left_wheel" type="mesh" contype="0" conaffinity="0" group="1" density="0" rgba="0.273909 0.273909 0.273909 1" mesh="wheel"/>
      <geom size="0.05 0.021" quat="0.707107 0.707107 0 0" type="cylinder" rgba="0.273909 0.273909 0.273909 1"/>
    </body>
    <body name="front_right_wheel_link" pos="0.1 -0.1 0.05">
      <inertial pos="-0.0002104 5.31e-05 -0.0004148" mass="0.162" diaginertia="0.0002 0.00012 0.00012"/>
      <joint name="front_right_wheel_joint" pos="0 0 0" axis="0 1 0"/>
      <geom name="front_right_wheel_bolt" size="0.007 0.0005" pos="0 -0.0145 0" quat="0.707107 0.707107 0 0" type="cylinder" contype="0" conaffinity="0" group="1" density="0" rgba="0.45 0.15 0 1"/>
      <geom name="front_right_wheel" type="mesh" contype="0" conaffinity="0" group="1" density="0" rgba="0.273909 0.273909 0.273909 1" mesh="wheel1"/>
      <geom size="0.05 0.021" quat="0.707107 0.707107 0 0" type="cylinder" rgba="0.273909 0.273909 0.273909 1"/>
    </body>
    <body name="rear_left_wheel_link" pos="-0.1 0.1 0.05">
      <inertial pos="-0.0002104 5.31e-05 -0.0004148" mass="0.162" diaginertia="0.0002 0.00012 0.00012"/>
      <joint name="rear_left_wheel_joint" pos="0 0 0" axis="0 1 0"/>
      <geom name="rear_left_wheel_bolt" size="0.007 0.0005" pos="0 0.0145 0" quat="0.707107 0.707107 0 0" type="cylinder" contype="0" conaffinity="0" group="1" density="0" rgba="0.45 0.15 0 1"/>
      <geom name="rear_left_wheel" type="mesh" contype="0" conaffinity="0" group="1" density="0" rgba="0.273909 0.273909 0.273909 1" mesh="wheel"/>
      <geom size="0.05 0.021" quat="0.707107 0.707107 0 0" type="cylinder" rgba="0.273909 0.273909 0.273909 1"/>
    </body>
    <body name="rear_right_wheel_link" pos="-0.1 -0.1 0.05">
      <inertial pos="-0.0002104 5.31e-05 -0.0004148" mass="0.162" diaginertia="0.0002 0.00012 0.00012"/>
      <joint name="rear_right_wheel_joint" pos="0 0 0" axis="0 1 0"/>
      <geom name="rear_right_wheel_bolt" size="0.007 0.0005" pos="0 -0.0145 0" quat="0.707107 0.707107 0 0" type="cylinder" contype="0" conaffinity="0" group="1" density="0" rgba="0.45 0.15 0 1"/>
      <geom name="rear_right_wheel" type="mesh" contype="0" conaffinity="0" group="1" density="0" rgba="0.273909 0.273909 0.273909 1" mesh="wheel"/>
      <geom size="0.05 0.021" quat="0.707107 0.707107 0 0" type="cylinder" rgba="0.273909 0.273909 0.273909 1"/>
    </body>
  </body>
  </worldbody>
</mujoco>
