<mujoco model="00_all_20240516.SLDASM">
    <compiler angle="radian" meshdir="./Allmesh/"/>
    <size njmax="500" nconmax="100" />
    <option gravity="0 0 -9.81" timestep="0.01"/>
    <asset>
        <mesh name="armor" file="robot_meshes/armor.stl"/>

        <texture name="ambulance_texture" type="2d" file="Allmesh/Environment/textures/ambulance.png" />
        <material name="ambulance_material" texture="ambulance_texture" />
        <mesh name="ambulance" file="Environment/meshes/ambulance.obj" scale="0.02 0.02 0.02"/>

        <texture name="suv_texture" type="2d" file="Allmesh/Environment/textures/suv.png" />
        <material name="suv_material" texture="suv_texture" />
        <mesh name="suv" file="Environment/meshes/suv.obj" scale="0.06 0.06 0.06"/>

        <texture name="apartment_texture" type="2d" file="Allmesh/Environment/textures/apartment_diffuse.png" />
        <material name="apartment_material" texture="apartment_texture" />
        <mesh name="apartment" file="Environment/meshes/apartment.obj" scale="0.02 0.02 0.02"/>


        <texture name="fire_station_texture" type="2d" file="Allmesh/Environment/textures/fire_station_diffuse.png" />
        <material name="fire_station_material" texture="apartment_texture" />
        <mesh name="fire_station" file="Environment/meshes/fire_station.obj" scale="0.02 0.02 0.02"/>

        <texture name="house_1_texture" type="2d" file="Allmesh/Environment/textures/House_1_Diffuse.png" />
        <material name="house_1_material" texture="house_1_texture" />
        <mesh name="house_1" file="Environment/meshes/house_1.obj" scale="0.04 0.04 0.04"/>
        
        <texture name="law_office_texture" type="2d" file="Allmesh/Environment/textures/law_office_diffuse.png" />
        <material name="law_office_material" texture="law_office_texture" />
        <mesh name="law_office" file="Environment/meshes/law_office.obj" scale="0.04 0.04 0.04"/>
        
        <texture name="mailbox_texture" type="2d" file="Allmesh/Environment/textures/Mailbox_Diffuse.png" />
        <material name="mailbox_material" texture="mailbox_texture" />
        <mesh name="mailbox" file="Environment/meshes/mailbox.obj" scale="0.04 0.04 0.04"/>

        <texture name="stop_light_texture" type="2d" file="Allmesh/Environment/textures/stop_light.png" />
        <material name="stop_light_material" texture="house_2_texture" />
        <mesh name="stop_light" file="Environment/meshes/stop_light.obj" scale="0.04 0.04 0.04"/>
        
        <texture name="house_2_texture" type="2d" file="Allmesh/Environment/textures/House_2_Diffuse.png" />
        <material name="house_2_material" texture="house_2_texture" />
        <mesh name="house_2" file="Environment/meshes/house_2.obj" scale="0.04 0.04 0.04"/>

        <texture name="tree_texture" type="2d" file="Allmesh/Environment/textures/branch_diffuse.png" />
        <material name="tree_material" texture="tree_texture" />
        <mesh name="tree" file="Environment/meshes/oak_tree_branch.obj" scale="0.8 0.8 0.8"/>

        <mesh name="battery" file="robot_meshes/battery.stl"/>
        <mesh name="battery_pin_left" file="robot_meshes/battery_pin_left.stl"/>
        <mesh name="battery_pin_right" file="robot_meshes/battery_pin_right.stl"/>
        <mesh name="chassis" file="robot_meshes/chassis.stl"/>
        <mesh name="controller" file="robot_meshes/controller.stl"/>
        <mesh name="controller_cover" file="robot_meshes/controller_cover.stl"/>
        <mesh name="base_collision" file="robot_meshes/base_collision.stl"/>
        <mesh name="hit_sensor" file="robot_meshes/hit_sensor.stl"/>
        <mesh name="led" file="robot_meshes/led.stl"/>
        <mesh name="wheel" file="robot_meshes/wheel.stl"/>
        <mesh name="wheel_mirror" file="robot_meshes/wheel_mirror.stl"/>
        <mesh name="blaster_bug" file="robot_meshes/blaster_bug.stl" scale="0.7949 0.7949 0.7949"/>
        <mesh name="blaster_gun" file="robot_meshes/blaster_gun.stl"/>
        <mesh name="blaster_magazin" file="robot_meshes/blaster_magazin.stl"/>
        <mesh name="blaster_top" file="robot_meshes/blaster_top.stl"/>
        <mesh name="blaster_gun_collision" file="robot_meshes/blaster_gun_collision.stl"/>
        <mesh name="blaster_magazin_collision" file="robot_meshes/blaster_magazin_collision.stl"/>
        <mesh name="blaster_top_collision" file="robot_meshes/blaster_top_collision.stl"/>
        <mesh name="gimbal_base" file="robot_meshes/gimbal_base.stl"/>
        <mesh name="gimbal_base_collision" file="robot_meshes/gimbal_base_collision.stl"/>
        <mesh name="gimbal_left_led" file="robot_meshes/gimbal_left_led.stl"/>
        <mesh name="gimbal_left_led_0" file="robot_meshes/gimbal_left_led_0.stl"/>
        <mesh name="gimbal_left_led_1" file="robot_meshes/gimbal_left_led_1.stl"/>
        <mesh name="gimbal_left_led_2" file="robot_meshes/gimbal_left_led_2.stl"/>
        <mesh name="gimbal_left_led_3" file="robot_meshes/gimbal_left_led_3.stl"/>
        <mesh name="gimbal_left_led_4" file="robot_meshes/gimbal_left_led_4.stl"/>
        <mesh name="gimbal_left_led_5" file="robot_meshes/gimbal_left_led_5.stl"/>
        <mesh name="gimbal_left_led_6" file="robot_meshes/gimbal_left_led_6.stl"/>
        <mesh name="gimbal_left_led_7" file="robot_meshes/gimbal_left_led_7.stl"/>
        <mesh name="gimbal_right_led_0" file="robot_meshes/gimbal_right_led_0.stl"/>
        <mesh name="gimbal_right_led_1" file="robot_meshes/gimbal_right_led_1.stl"/>
        <mesh name="gimbal_right_led_2" file="robot_meshes/gimbal_right_led_2.stl"/>
        <mesh name="gimbal_right_led_3" file="robot_meshes/gimbal_right_led_3.stl"/>
        <mesh name="gimbal_right_led_4" file="robot_meshes/gimbal_right_led_4.stl"/>
        <mesh name="gimbal_right_led_5" file="robot_meshes/gimbal_right_led_5.stl"/>
        <mesh name="gimbal_right_led_6" file="robot_meshes/gimbal_right_led_6.stl"/>
        <mesh name="gimbal_right_led7" file="robot_meshes/gimbal_right_led7.stl"/>
        <mesh name="gimbal" file="robot_meshes/gimbal.stl"/>
        <mesh name="gimbal_left_armor" file="robot_meshes/gimbal_left_armor.stl"/>
        <mesh name="gimbal_right_armor" file="robot_meshes/gimbal_right_armor.stl"/>
        <mesh name="gimbal_side" file="robot_meshes/gimbal_side.stl"/>
        <mesh name="gimbal_collision" file="robot_meshes/gimbal_collision.stl"/>
        <mesh name="speaker" file="robot_meshes/speaker.stl"/>
        <mesh name="speaker_collision" file="robot_meshes/speaker_collision.stl"/>
        <mesh name="camera" file="robot_meshes/camera.stl" scale="1 1 1"/>
        <mesh name="intelligent_controller" file="robot_meshes/intelligent_controller.stl"/>
        <mesh name="wifi_antenna_left" file="robot_meshes/wifi_antenna_left.stl"/>
        <mesh name="wifi_antenna_right" file="robot_meshes/wifi_antenna_right.stl"/>
        <mesh name="base_link" file="robot_meshes/base_link_new.STL" />
        <mesh name="left_steering_link" file="robot_meshes/left_steering_link.STL" />
        <mesh name="right_steering_link" file="robot_meshes/right_steering_link.STL" />
        <mesh name="apollo_front_left_wheel_Link" file="robot_meshes/front_left_wheel_Link.STL" />
        <mesh name="apollo_front_right_wheel_Link" file="robot_meshes/front_right_wheel_Link.STL" />
        <mesh name="apollo_rear_left_wheel_Link" file="robot_meshes/rear_left_wheel_Link.STL" />
        <mesh name="apollo_rear_right_wheel_Link" file="robot_meshes/rear_right_wheel_Link.STL" />
        <mesh name="handle_Link" file="robot_meshes/handle_Link.STL" />
        <mesh name="plane_Link" file="robot_meshes/plane_Link.STL" />
        
        <!-- <texture builtin="checker" height="100" name="texplane" rgb1="1 1 1" rgb2="0.8 0.8 0.8" type="2d" width="100"/>
        <material name="MatPlane" reflectance="0.5" shininess="1" specular="1" texrepeat="60 60" texture="texplane"/> -->

        <texture name="road_texture" type="2d" file="Allmesh/Environment/textures/road_texture.png" />
        <material name="MatPlane" texture="road_texture"/>
    </asset>
    <visual>
    <headlight diffuse="2 2 2" specular="0.5 0.5 0.5"/>
    </visual>
    <worldbody>
    
    <!-- <light name="global_light" pos="-10 0 30" dir="0 0 -1" diffuse="10 10 10" specular="1 1 1" /> -->
    <geom conaffinity="1" condim="3" material="MatPlane" friction=".5 0.005 0.0001" name="floor" pos="0 0 0" rgba="0.8 0.9 0.8 1" size="90 90 90" type="plane"/>
    <!-- <geom name="wall1" size="2 0.1 0.5" pos="-1 -3 0.3" type="box" rgba="0.8 0.8 0.8 1"/>
    <geom name="wall2" size="2 0.1 0.5" pos="3.5 -3 0.3" type="box" rgba="0.8 0.8 0.8 1"/>
    <geom name="wall3" size="0.1 3 0.5" pos="-3 -6 0.3" type="box" rgba="0.8 0.8 0.8 1"/>
    <geom name="wall4" size="0.1 3 0.5" pos="5.5 -6 0.3" type="box" rgba="0.8 0.8 0.8 1"/>
    <geom name="wall5" size="4.25 0.1 0.5" pos="1.25 -9 0.3" type="box" rgba="0.8 0.8 0.8 1"/> -->

    <body name="apartment" pos="-20 23 0" quat="1 0 0 1">
        <inertial pos="0 0 0" quat="0 0 0 1" mass="4.37453" diaginertia="0.0565948 0.0315356 0.0315351" />
        <geom type="mesh"  contype="1" conaffinity="0" group="1" mesh="apartment" material='apartment_material'/>
      </body>


      <body name="house_1" pos="-50 23 0" quat="0 0 0 1">
        <inertial pos="0 0 0" quat="0 0 0 1" mass="4.37453" diaginertia="0.0565948 0.0315356 0.0315351" />
        <geom type="mesh"  contype="1" conaffinity="0" group="1" mesh="house_1" material='house_1_material'/>
      </body>

      <body name="suv" pos="-57 -7 0" quat="1 0 0 1">
        <inertial pos="0 0 0" quat="0 0 0 1" mass="4.37453" diaginertia="0.0565948 0.0315356 0.0315351" />
        <geom type="mesh"  contype="1" conaffinity="0" group="1" mesh="suv" material='suv_material'/>
        <geom name="suv_front_right_wheel" size="0.5 0.2" pos="-1 2 0.42" quat="0.707107  0 0.707107 0" type="cylinder" contype="1" conaffinity="0" group="1" density="0" rgba="0 0 0 1"/>
        <geom name="suv_front_left_wheel" size="0.5 0.2" pos="1 2 0.42" quat="0.707107  0 0.707107 0" type="cylinder" contype="1" conaffinity="0" group="1" density="0" rgba="0 0 0 1"/>
        <geom name="suv_rear_right_wheel" size="0.5 0.2" pos="-1 -1.6 0.42" quat="0.707107  0 0.707107 0" type="cylinder" contype="1" conaffinity="0" group="1" density="0" rgba="0 0 0 1"/>
        <geom name="suv_rear_left_wheel" size="0.5 0.2" pos="1 -1.6 0.42" quat="0.707107  0 0.707107 0" type="cylinder" contype="1" conaffinity="0" group="1" density="0" rgba="0 0 0 1"/>
      </body>

      <body name="ambulance" pos="-35 7 0" quat="1 0 0 1">
        <inertial pos="0 0 0" quat="0 0 0 1" mass="4.37453" diaginertia="0.0565948 0.0315356 0.0315351" />
        <geom type="mesh"  contype="1" conaffinity="0" group="1" mesh="ambulance" material='ambulance_material'/>
        <geom name="ambulance_rear_right_wheel" size="0.33 0.15" pos="-0.9 1.29 0.3" quat="0.707107  0 0.707107 0" type="cylinder" contype="1" conaffinity="0" group="1" density="0" rgba="0 0 0 1"/>
        <geom name="ambulance_rear_left_wheel" size="0.33 0.15" pos="0.9 1.29 0.3" quat="0.707107  0 0.707107 0" type="cylinder" contype="1" conaffinity="0" group="1" density="0" rgba="0 0 0 1"/>
        <geom name="ambulance_front_right_wheel" size="0.33 0.15" pos="-0.85 -2.25 0.3" quat="0.707107  0 0.707107 0" type="cylinder" contype="1" conaffinity="0" group="1" density="0" rgba="0 0 0 1"/>
        <geom name="ambulance_front_left_wheel" size="0.33 0.15" pos="0.85 -2.25 0.3" quat="0.707107  0 0.707107 0" type="cylinder" contype="1" conaffinity="0" group="1" density="0" rgba="0 0 0 1"/>
      </body>

      <body name="law_office" pos="-20 -23 0" quat="0 0 0 1">
        <inertial pos="0 0 0" quat="0 0 0 1" mass="4.37453" diaginertia="0.0565948 0.0315356 0.0315351" />
        <geom type="mesh"  contype="1" conaffinity="0" group="1" mesh="law_office" material='law_office_material'/>
      </body>
      <body name="fire_station" pos="-40 -23 0" quat="0 0 0 1">
        <inertial pos="0 0 0" quat="0 0 0 1" mass="4.37453" diaginertia="0.0565948 0.0315356 0.0315351" />
        <geom type="mesh"  contype="1" conaffinity="0" group="1" mesh="fire_station" material='fire_station_material'/>
      </body>

      <body name="house_2" pos="-60 -23 0" quat="0 0 0 -1">
        <inertial pos="0 0 0" quat="0 0 0 1" mass="4.37453" diaginertia="0.0565948 0.0315356 0.0315351" />
        <geom type="mesh"  contype="1" conaffinity="0" group="1" mesh="house_2" material='house_2_material'/>
      </body>

      <body name="mailbox1" pos="-45 15 0" quat="0 0 0 -1">
        <inertial pos="0 0 0" quat="0 0 0 1" mass="4.37453" diaginertia="0.0565948 0.0315356 0.0315351" />
        <geom type="mesh"  contype="1" conaffinity="0" group="1" mesh="mailbox" material='mailbox_material'/>
      </body>

      <body name="mailbox2" pos="-15 15 0" quat="0 0 0 -1">
        <inertial pos="0 0 0" quat="0 0 0 1" mass="4.37453" diaginertia="0.0565948 0.0315356 0.0315351" />
        <geom type="mesh"  contype="1" conaffinity="0" group="1" mesh="mailbox" material='mailbox_material'/>
      </body>

      <body name="stop_light" pos="0 0 3.5" quat="-1 0 0 1">
        <inertial pos="0 0 0" quat="0 0 0 1" mass="4.37453" diaginertia="0.0565948 0.0315356 0.0315351" />
        <geom type="mesh"  contype="1" conaffinity="0" group="1" mesh="stop_light" material='stop_light_material'/>
      </body>

      <body name="tree_1" pos="-10 12 0" quat="-1 0 0 1">
        <inertial pos="0 0 0" quat="0 0 0 1" mass="4.37453" diaginertia="0.0565948 0.0315356 0.0315351" />
        <geom size="0.1 5" pos="0 0.0145 0" quat="0 0 0 1" type="cylinder" contype="1" conaffinity="0" group="1" density="0" rgba="0.45 0.15 0 1"/>
        <geom type="mesh"  pos="0 0 2" contype="1" conaffinity="0" group="1" mesh="tree" material='tree_material'/>
      </body>

      <body name="tree_2" pos="-20 -12 0" quat="-1 0 0 1">
        <inertial pos="0 0 0" quat="0 0 0 1" mass="4.37453" diaginertia="0.0565948 0.0315356 0.0315351" />
        <geom size="0.1 5" pos="0 0.0145 0" quat="0 0 0 1" type="cylinder" contype="1" conaffinity="0" group="1" density="0" rgba="0.45 0.15 0 1"/>
        <geom type="mesh"  pos="0 0 2" contype="1" conaffinity="0" group="1" mesh="tree" material='tree_material'/>
      </body>

      <body name="tree_3" pos="-35 12 0" quat="-1 0 0 1">
        <inertial pos="0 0 0" quat="0 0 0 1" mass="4.37453" diaginertia="0.0565948 0.0315356 0.0315351" />
        <geom size="0.1 5" pos="0 0.0145 0" quat="0 0 0 1" type="cylinder" contype="1" conaffinity="0" group="1" density="0" rgba="0.45 0.15 0 1"/>
        <geom type="mesh"  pos="0 0 2" contype="1" conaffinity="0" group="1" mesh="tree" material='tree_material'/>
      </body>

      <body name="tree_4" pos="-35 -12 0" quat="-1 0 0 1">
        <inertial pos="0 0 0" quat="0 0 0 1" mass="4.37453" diaginertia="0.0565948 0.0315356 0.0315351" />
        <geom size="0.1 5" pos="0 0.0145 0" quat="0 0 0 1" type="cylinder" contype="1" conaffinity="0" group="1" density="0" rgba="0.45 0.15 0 1"/>
        <geom type="mesh"  pos="0 0 2" contype="1" conaffinity="0" group="1" mesh="tree" material='tree_material'/>
      </body>

      <body name="tree_5" pos="-50 12 0" quat="-1 0 0 1">
        <inertial pos="0 0 0" quat="0 0 0 1" mass="4.37453" diaginertia="0.0565948 0.0315356 0.0315351" />
        <geom size="0.1 5" pos="0 0.0145 0" quat="0 0 0 1" type="cylinder" contype="1" conaffinity="0" group="1" density="0" rgba="0.45 0.15 0 1"/>
        <geom type="mesh"  pos="0 0 2" contype="1" conaffinity="0" group="1" mesh="tree" material='tree_material'/>
      </body>

      <body name="tree_6" pos="-50 -12 0" quat="-1 0 0 1">
        <inertial pos="0 0 0" quat="0 0 0 1" mass="4.37453" diaginertia="0.0565948 0.0315356 0.0315351" />
        <geom size="0.1 5" pos="0 0.0145 0" quat="0 0 0 1" type="cylinder" contype="1" conaffinity="0" group="1" density="0" rgba="0.45 0.15 0 1"/>
        <geom type="mesh"  pos="0 0 2" contype="1" conaffinity="0" group="1" mesh="tree" material='tree_material'/>
      </body>

      <body name="tree_7" pos="-65 12 0" quat="-1 0 0 1">
        <inertial pos="0 0 0" quat="0 0 0 1" mass="4.37453" diaginertia="0.0565948 0.0315356 0.0315351" />
        <geom size="0.1 5" pos="0 0.0145 0" quat="0 0 0 1" type="cylinder" contype="1" conaffinity="0" group="1" density="0" rgba="0.45 0.15 0 1"/>
        <geom type="mesh"  pos="0 0 2" contype="1" conaffinity="0" group="1" mesh="tree" material='tree_material'/>
      </body>

      <body name="tree_8" pos="-65 -12 0" quat="-1 0 0 1">
        <inertial pos="0 0 0" quat="0 0 0 1" mass="4.37453" diaginertia="0.0565948 0.0315356 0.0315351" />
        <geom size="0.1 5" pos="0 0.0145 0" quat="0 0 0 1" type="cylinder" contype="1" conaffinity="0" group="1" density="0" rgba="0.45 0.15 0 1"/>
        <geom type="mesh"  pos="0 0 2" contype="1" conaffinity="0" group="1" mesh="tree" material='tree_material'/>
      </body>

      

       


    
    <body name="apollo_base" pos="-80 5 0" quat="1 1 0 0">
      <freejoint/>
        <geom type="mesh" contype="1" conaffinity="0" group="1" rgba="0.239216 0.317647 0.227451 1" mesh="base_link" density="1500"/>
        <body name="right_steering_link" pos="0.3125 0.1182 0.1792" quat="0.707105 0.707108 0 0">
            <inertial pos="6.8053e-08 0.0481378 -0.0356571" quat="0.626113 0.779732 5.58039e-06 -2.89094e-06" mass="0.176526" diaginertia="0.000398379 0.000350283 7.39585e-05" />
            <joint name="right_steering_joint" pos="0 0 0" axis="0 0 -1" limited="true" range="-0.5 0.5"/>
            <geom type="mesh" contype="1" conaffinity="0" group="1" rgba="0.584314 0.584314 0.584314 1" mesh="right_steering_link" />
            <body name="apollo_front_right_wheel_link" pos="0 0.1058 -0.0288">
                <inertial pos="0 2.5429e-06 0" quat="0.438658 0.554598 0.554598 0.438658" mass="4.37454" diaginertia="0.0565948 0.0315356 0.0315351" />
                <joint name="apollo_front_right_wheel_joint" pos="0 0 0" axis="0 1 0" />
                <geom type="mesh" contype="1" conaffinity="0" group="1" rgba="0.0980392 0.0980392 0.0980392 1" mesh="apollo_front_right_wheel_Link" />
            </body>
            <!-- <light name="tracking_ap_light" pos="0 0 20" dir="0 0 -1" diffuse="10 10 10"/> -->
        </body>
        <body name="left_steering_link" pos="0.3125 0.1182 -0.1792" quat="0.707105 0.707108 0 0">
            <inertial pos="3.48168e-07 -0.0481376 -0.0356571" quat="0.779732 0.626113 -6.81975e-06 3.27842e-06" mass="0.176527" diaginertia="0.000398382 0.000350288 7.39596e-05" />
            <joint name="left_steering_joint" pos="0 0 0" axis="0 0 -1" limited="true" range="-0.5 0.5" />
            <geom type="mesh" contype="1" conaffinity="0" group="1" rgba="0.584314 0.584314 0.584314 1" mesh="left_steering_link" />
            <body name="apollo_front_left_wheel_link" pos="0 -0.1058 -0.0288" quat="-3.67321e-06 1 0 0">
                <inertial pos="0 2.5429e-06 0" quat="0.438658 0.554598 0.554598 0.438658" mass="4.37453" diaginertia="0.0565948 0.0315356 0.0315351" />
                <joint name="apollo_front_left_wheel_joint" pos="0 0 0" axis="0 1 0" />
                <geom type="mesh" contype="1" conaffinity="0" group="1" rgba="0.0980392 0.0980392 0.0980392 1" mesh="apollo_front_left_wheel_Link" />
            </body>
        </body>
        <body name="apollo_rear_left_wheel_Link" pos="-0.3125 0.147 -0.285" quat="0.707105 -0.707108 0 0">
            <inertial pos="0 2.54252e-06 0" quat="0.494999 0.504951 0.504951 0.494999" mass="4.37454" diaginertia="0.0565948 0.0315357 0.0315351" />
            <joint name="apollo_rear_left_wheel_joint" pos="0 0 0" axis="0 1 0" />
            <geom type="mesh" contype="1" conaffinity="0" group="1" rgba="0.0941176 0.0941176 0.0941176 1" mesh="apollo_rear_left_wheel_Link" />
        </body>
        <body name="apollo_rear_right_wheel_Link" pos="-0.3125 0.147 0.285" quat="0.707105 0.707108 0 0">
            <inertial pos="0 2.54252e-06 0" quat="0.494999 0.504951 0.504951 0.494999" mass="4.37454" diaginertia="0.0565948 0.0315357 0.0315351" />
            <joint name="apollo_rear_right_wheel_joint" pos="0 0 0" axis="0 1 0" />
            <geom type="mesh" contype="1" conaffinity="0" group="1" rgba="0.0941176 0.0941176 0.0941176 1" mesh="apollo_rear_right_wheel_Link" />
        </body>
        <body name="handle_Link" pos="-0.4345 0.853 0.406" quat="1.34924e-11 3.67321e-06 -1 -3.67321e-06" gravcomp="1">
            <inertial pos="-0.234705 -0.0584311 0.0186125" quat="0.505098 0.500862 -0.499441 0.494542" mass="0.475034" diaginertia="0.00171862 0.00125326 0.00063586" />
            <joint name="handle_joint" pos="0 0 0" axis="0 1 0" type="slide" limited="true" range="-0.63 0" />
            <geom type="mesh" contype="1" conaffinity="0" group="1" rgba="0.305882 0.32549 0.352941 1" mesh="handle_Link" />
            <body name="plane_Link" pos="-0.4345 -0.2 0.036" quat="1.34924e-11 3.67321e-06 -1 -3.67321e-06" gravcomp="1">
                <inertial pos="-0.180014 0.759611 0.384771" quat="-0.00113978 0.707107 -0.000387157 0.707106" mass="0.470939" diaginertia="0.00535856 0.00360992 0.0017562" />
                <joint name="plane_joint" pos="0 0 0" axis="1 0 0" limited="true" range="0 1.6" />
                <geom pos="0 -0.653 -0.37" type="mesh" contype="1" conaffinity="0" group="1" rgba="0.305882 0.32549 0.352941 1" mesh="plane_Link" />
            </body>
        </body>
    </body>
    <!-- <body name="rm_base" pos="-61 4.2 0" mocap="true" quat="-1 0 0 -1" gravcomp="1"> -->
    <body name="rm_base" pos="-80.2 5 0.63" mocap="true" quat="1 0 0 1" gravcomp="1">
    <site name="lidar_site" pos="0 0 0.19484" size="0.01" rgba="1 0 0 1"/>
    <geom name="armor" pos="-0.0064553 -0.078141 0.0639377" quat="1 0 0 0" type="mesh" contype="1" conaffinity="0" group="1" density="0" rgba="0.227713 0.227713 0.227713 0.8" mesh="armor"/>
    <geom name="battery" pos="-0.130336 -0.0018702 0.0520677" quat="1 0 0 0" type="mesh" contype="1" conaffinity="0" group="1" density="0" rgba="0.0281746 0.0281746 0.0281746 1" mesh="battery"/>
    <geom name="battery_pin_left" pos="-0.115891 0.066115 0.0871743" quat="1 0 0 0" type="mesh" contype="1" conaffinity="0" group="1" density="0" rgba="0.0281746 0.0281746 0.0281746 1" mesh="battery_pin_left"/>
    <geom name="battery_pin_right" pos="-0.115891 -0.0658844 0.0871743" quat="1 0 0 0" type="mesh" contype="1" conaffinity="0" group="1" density="0" rgba="0.0281746 0.0281746 0.0281746 1" mesh="battery_pin_right"/>
    <geom name="chassis" pos="-0.0059039 0.0004154 0.0874455" quat="1 0 0 0" type="mesh" contype="1" conaffinity="0" group="1" density="0" rgba="0.0981132 0.0981132 0.0981132 1" mesh="chassis"/>
    <geom name="controller" pos="-0.114229 -0.0006716 0.087325" quat="1 0 0 0" type="mesh" contype="1" conaffinity="0" group="1" density="0" rgba="0.0281746 0.0281746 0.0281746 1" mesh="controller"/>
    <geom name="controller_cover" pos="-0.0787757 -0.002522 0.106733" quat="1 0 0 0" type="mesh" contype="1" conaffinity="0" group="1" density="0" rgba="0.254832 0.254832 0.254832 0.3" mesh="controller_cover"/>
    <geom name="front_hit_sensor" pos="0.156999 -0.0004276 0.0779362" quat="1 0 0 0" type="mesh" contype="1" conaffinity="0" group="1" density="0" rgba="0.169785 0.169785 0.169785 1" mesh="hit_sensor"/>
    <geom name="front_led" pos="0.165741 -0.0017117 0.0779737" quat="1 0 0 0" type="mesh" contype="1" conaffinity="0" group="1" density="0" rgba="0 0.777358 0.777358 1" mesh="led"/>
    <geom name="left_hit_sensor" pos="-0.0024413 0.0886932 0.0644841" quat="0.707107 0 0 0.707107" type="mesh" contype="1" conaffinity="0" group="1" density="0" rgba="0.169785 0.169785 0.169785 1" mesh="hit_sensor"/>
    <geom name="left_led" pos="-0.0011572 0.097436 0.0645216" quat="0.707107 0 0 0.707107" type="mesh" contype="1" conaffinity="0" group="1" density="0" rgba="0 0.777358 0.777358 1" mesh="led"/>
    <geom name="rear_hit_sensor" pos="-0.158183 -0.0027864 0.0650168" quat="0 0 0 1" type="mesh" contype="1" conaffinity="0" group="1" density="0" rgba="0.169785 0.169785 0.169785 1" mesh="hit_sensor"/>
    <geom name="rear_led" pos="-0.166926 -0.0015023 0.0650543" quat="0 0 0 1" type="mesh" contype="1" conaffinity="0" group="1" density="0" rgba="0 0.777358 0.777358 1" mesh="led"/>
    <geom name="right_hit_sensor" pos="-0.0024413 -0.0886932 0.0644841" quat="0.707107 0 0 -0.707107" type="mesh" contype="1" conaffinity="0" group="1" density="0" rgba="0.169785 0.169785 0.169785 1" mesh="hit_sensor"/>
    <geom name="right_led" pos="-0.0037254 -0.097436 0.0645216" quat="0.707107 0 0 -0.707107" type="mesh" contype="1" conaffinity="0" group="1" density="0" rgba="0 0.777358 0.777358 1" mesh="led"/>
    <geom name="gimbal_base" pos="-0.002 0 0.118" quat="1 0 0 0" type="mesh" contype="1" conaffinity="0" group="1" density="0" rgba="0.12595 0.12595 0.12595 1" mesh="gimbal_base"/>
    <geom name="gimbal" pos="-0.00202 -0.001 0.15169" quat="1 0 0 0" type="mesh" contype="1" conaffinity="0" group="1" density="0" rgba="0.12595 0.12595 0.12595 1" mesh="gimbal"/>
    <geom name="gimbal_left_armor" pos="-0.00672 0.06418 0.18922" quat="1 0 0 0" type="mesh" contype="1" conaffinity="0" group="1" density="0" rgba="0.06401 0.06401 0.06401 1" mesh="gimbal_left_armor"/>
    <geom name="gimbal_right_armor" pos="-0.00727 -0.06277 0.19114" quat="1 0 0 0" type="mesh" contype="1" conaffinity="0" group="1" density="0" rgba="0.06401 0.06401 0.06401 1" mesh="gimbal_right_armor"/>
    <geom name="gimbal_side" pos="-0.00227 0.00034 0.20555" quat="1 0 0 0" type="mesh" contype="1" conaffinity="0" group="1" density="0" rgba="0.01758 0.01758 0.01758 1" mesh="gimbal_side"/>
    <geom name="blaster_bug" pos="-0.00198 -0.03893 0.21319" quat="1 0 0 0" type="mesh" contype="1" conaffinity="0" group="1" density="0" rgba="0.06401 0.06401 0.06401 1" mesh="blaster_bug"/>
    <geom name="blaster_gun" pos="0.03669 0.0036 0.19484" quat="1 0 0 0" type="mesh" contype="1" conaffinity="0" group="1" density="0" rgba="0.06401 0.06401 0.06401 1" mesh="blaster_gun"/>
    <geom name="blaster_magazin" pos="-0.02258 0.00035 0.23421" quat="1 0 0 0" type="mesh" contype="1" conaffinity="0" group="1" density="0" rgba="0.76578 0.76578 0.76578 1" mesh="blaster_magazin"/>
    <geom name="blaster_top" pos="-0.00087 0.00116 0.22258" quat="1 0 0 0" type="mesh" contype="1" conaffinity="0" group="1" density="0" rgba="0.47861 0.47861 0.47861 1" mesh="blaster_top"/>
    <geom name="speaker" pos="-0.01528 0.00725 0.14438" quat="1 0 0 0" type="mesh" contype="1" conaffinity="0" group="1" density="0" mesh="speaker"/>
    <geom name="camera" pos="0.0701244 0.00034 0.236979" quat="0.996195 0 -0.0871539 0" type="mesh" contype="1" conaffinity="0" group="1" density="0" rgba="0.0281746 0.028 0.0281746 1" mesh="camera"/>
    <geom name="intelligent_controller" pos="-0.02927 0.00034 0.266027" quat="1 0 0 0" type="mesh" contype="1" conaffinity="0" group="1" density="0" rgba="0.8 0.8 0.8 1" mesh="intelligent_controller"/>
    <geom name="wifi_antenna_left" pos="-0.0439805 0.0348187 0.278837" quat="1 0 0 0" type="mesh" contype="1" conaffinity="0" group="1" density="0" rgba="0.8 0.8 0.8 1" mesh="wifi_antenna_left"/>
    <geom name="wifi_antenna_right" pos="-0.0439825 -0.0347998 0.27975" quat="1 0 0 0" type="mesh" contype="1" conaffinity="0" group="1" density="0" rgba="0.8 0.8 0.8 1" mesh="wifi_antenna_right"/>
    <geom name="top" size="0.0544865 0.0295514 0.0114575" pos="-0.0061042 0.0003198 0.264166" type="box" rgba="0.8 0.8 0.8 1" contype="1" conaffinity="0" group="1"/>
    <geom name="gimbal_left_led" pos="-0.02631 0.07079 0.22176" quat="1 0 0 0" type="mesh" contype="1" conaffinity="0" group="1" density="0" rgba="0.78118 0.78118 0.78118 1" mesh="gimbal_left_led"/>
    <geom name="gimbal_left_led0" pos="-0.02533 0.07079 0.18827" quat="1 0 0 0" type="mesh" contype="1" conaffinity="0" group="1" density="0" rgba="0.78118 0.78118 0.78118 1" mesh="gimbal_left_led_0"/>
    <geom name="gimbal_left_led1" pos="-0.01005 0.07079 0.17784" quat="1 0 0 0" type="mesh" contype="1" conaffinity="0" group="1" density="0" rgba="0.78118 0.78118 0.78118 1" mesh="gimbal_left_led_1"/>
    <geom name="gimbal_left_led2" pos="0.00859 0.07079 0.17874" quat="1 0 0 0" type="mesh" contype="1" conaffinity="0" group="1" density="0" rgba="0.78118 0.78118 0.78118 1" mesh="gimbal_left_led_2"/>
    <geom name="gimbal_left_led3" pos="0.0226 0.07079 0.1906" quat="1 0 0 0" type="mesh" contype="1" conaffinity="0" group="1" density="0" rgba="0.78118 0.78118 0.78118 1" mesh="gimbal_left_led_3"/>
    <geom name="gimbal_left_led4" pos="0.02121 0.07075 0.22233" quat="1 0 0 0" type="mesh" contype="1" conaffinity="0" group="1" density="0" rgba="0.78118 0.78118 0.78118 1" mesh="gimbal_left_led_4"/>
    <geom name="gimbal_left_led5" pos="0.00706 0.07079 0.23264" quat="1 0 0 0" type="mesh" contype="1" conaffinity="0" group="1" density="0" rgba="0.78118 0.78118 0.78118 1" mesh="gimbal_left_led_5"/>
    <geom name="gimbal_left_led6" pos="-0.01119 0.0708 0.2327" quat="1 0 0 0" type="mesh" contype="1" conaffinity="0" group="1" density="0" rgba="0.78118 0.78118 0.78118 1" mesh="gimbal_left_led_6"/>
    <geom name="gimbal_left_led7" pos="-0.02631 0.07079 0.22176" quat="1 0 0 0" type="mesh" contype="1" conaffinity="0" group="1" density="0" rgba="0.78118 0.78118 0.78118 1" mesh="gimbal_left_led_7"/>
    <geom name="gimbal_right_led0" pos="-0.02532 -0.0695 0.18827" quat="1 0 0 0" type="mesh" contype="1" conaffinity="0" group="1" density="0" rgba="0.78118 0.78118 0.78118 1" mesh="gimbal_right_led_0"/>
    <geom name="gimbal_right_led1" pos="-0.01005 -0.06952 0.17783" quat="1 0 0 0" type="mesh" contype="1" conaffinity="0" group="1" density="0" rgba="0.78118 0.78118 0.78118 1" mesh="gimbal_right_led_1"/>
    <geom name="gimbal_right_led2" pos="0.00859 -0.06952 0.17874" quat="1 0 0 0" type="mesh" contype="1" conaffinity="0" group="1" density="0" rgba="0.78118 0.78118 0.78118 1" mesh="gimbal_right_led_2"/>
    <geom name="gimbal_right_led3" pos="0.0226 -0.06952 0.1906" type="mesh" contype="1" conaffinity="0" group="1" density="0" rgba="0.78118 0.78118 0.78118 1" mesh="gimbal_right_led_3"/>
    <geom name="gimbal_right_led4" pos="0.02122 -0.06924 0.22232" quat="1 0 0 0" type="mesh" contype="1" conaffinity="0" group="1" density="0" rgba="0.78118 0.78118 0.78118 1" mesh="gimbal_right_led_4"/>
    <geom name="gimbal_right_led5" pos="0.00706 -0.06933 0.2327" quat="1 0 0 0" type="mesh" contype="1" conaffinity="0" group="1" density="0" rgba="0.78118 0.78118 0.78118 1" mesh="gimbal_right_led_5"/>
    <geom name="gimbal_right_led6" pos="-0.01125 -0.06933 0.23267" quat="1 0 0 0" type="mesh" contype="1" conaffinity="0" group="1" density="0" rgba="0.78118 0.78118 0.78118 1" mesh="gimbal_right_led_6"/>
    <geom name="gimbal_right_led7" pos="-0.02631 -0.06933 0.22176" type="mesh" contype="1" conaffinity="0" group="1" density="0" rgba="0.78118 0.78118 0.78118 1" mesh="gimbal_right_led7"/>
    

    <!-- <joint armature="0" axis="1 0 0" damping="0" limited="false" name="rm_x" pos="0 0 0" stiffness="0" type="slide"/>
    <joint armature="0" axis="0 1 0" damping="0" limited="false" name="rm_y" pos="0 0 0" stiffness="0" type="slide"/>
    <joint armature="0" axis="0 0 1" damping="0" limited="false" name="rm_z" pos="0 0 0" stiffness="0" type="slide"/>
    <joint armature="0" axis="0 0 1" damping="0" limited="false" name="rot_z" pos="0 0 0" stiffness="0" type="hinge"/> -->
    <body name="rm_front_left_wheel_link" pos="0.1 0.1 0.05" gravcomp="1">
      <inertial pos="-0.0002104 5.31e-05 -0.0004148" mass="0.162" diaginertia="0.0002 0.00012 0.00012"/>
      <joint name="rm_front_left_wheel_joint" pos="0 0 0" axis="0 1 0"/>
      <geom name="front_left_wheel_bolt" size="0.007 0.0005" pos="0 0.0145 0" quat="0.707107 0.707107 0 0" type="cylinder" contype="1" conaffinity="0" group="1" density="0" rgba="0.45 0.15 0 1"/>
      <geom name="front_left_wheel" type="mesh" contype="0" conaffinity="0" group="1" density="0" rgba="0.273909 0.273909 0.273909 1" mesh="wheel" friction="0 0 0"/>
    </body>
    <body name="rm_front_right_wheel_link" pos="0.1 -0.1 0.05" gravcomp="1">
      <inertial pos="-0.0002104 5.31e-05 -0.0004148" mass="0.162" diaginertia="0.0002 0.00012 0.00012"/>
      <joint name="rm_front_right_wheel_joint" pos="0 0 0" axis="0 1 0"/>
      <geom name="front_right_wheel_bolt" size="0.007 0.0005" pos="0 -0.0145 0" quat="0.707107 0.707107 0 0" type="cylinder" contype="1" conaffinity="0" group="1" density="0" rgba="0.45 0.15 0 1"/>
      <geom name="front_right_wheel" type="mesh" contype="1" conaffinity="0" group="1" density="0" rgba="0.273909 0.273909 0.273909 1" mesh="wheel_mirror" friction="0 0 0"/>
    </body>
    <body name="rm_rear_left_wheel_link" pos="-0.1 0.1 0.05" gravcomp="1">
      <inertial pos="-0.0002104 5.31e-05 -0.0004148" mass="0.162" diaginertia="0.0002 0.00012 0.00012"/>
      <joint name="rm_rear_left_wheel_joint" pos="0 0 0" axis="0 1 0"/>
      <geom name="rear_left_wheel_bolt" size="0.007 0.0005" pos="0 0.0145 0" quat="0.707107 0.707107 0 0" type="cylinder" contype="1" conaffinity="0" group="1" density="0" rgba="0.45 0.15 0 1"/>
      <geom name="rear_left_wheel" type="mesh" contype="1" conaffinity="0" group="1" density="0" rgba="0.273909 0.273909 0.273909 1" mesh="wheel_mirror" friction="0 0 0"/>
    </body>
    <body name="rm_rear_right_wheel_link" pos="-0.1 -0.1 0.05" gravcomp="1">
      <inertial pos="-0.0002104 5.31e-05 -0.0004148" mass="0.162" diaginertia="0.0002 0.00012 0.00012"/>
      <joint name="rm_rear_right_wheel_joint" pos="0 0 0" axis="0 1 0"/>
      <geom name="rear_right_wheel_bolt" size="0.007 0.0005" pos="0 -0.0145 0" quat="0.707107 0.707107 0 0" type="cylinder" contype="1" conaffinity="0" group="1" density="0" rgba="0.45 0.15 0 1"/>
      <geom name="rear_right_wheel" type="mesh" contype="1" conaffinity="0" group="1" density="0" rgba="0.273909 0.273909 0.273909 1" mesh="wheel" friction="0 0 0"/>
    <!-- <light name="tracking_rm_light" pos="0 0 20" dir="0 0 -1" diffuse="10 10 10"/> -->
    <!-- <camera name="rm_track_cam" pos="0 0 5" quat="0 0 0 -1"/> -->
    </body>
  </body>
    <!-- <body name="rm_base_2" pos="-57 3 0" mocap="true" quat="-1 0 0 -1" gravcomp="1"> -->
    <body name="rm_base_2" pos="-79.8 5 0.63" mocap="true" quat="1 0 0 1" gravcomp="1">
    <geom name="armor_2" pos="-0.0064553 -0.078141 0.0639377" quat="1 0 0 0" type="mesh" contype="1" conaffinity="0" group="1" density="0" rgba="0.227713 0.227713 0.227713 0.8" mesh="armor"/>
    <geom name="battery_2" pos="-0.130336 -0.0018702 0.0520677" quat="1 0 0 0" type="mesh" contype="1" conaffinity="0" group="1" density="0" rgba="0.0281746 0.0281746 0.0281746 1" mesh="battery"/>
    <geom name="battery_pin_left_2" pos="-0.115891 0.066115 0.0871743" quat="1 0 0 0" type="mesh" contype="1" conaffinity="0" group="1" density="0" rgba="0.0281746 0.0281746 0.0281746 1" mesh="battery_pin_left"/>
    <geom name="battery_pin_right_2" pos="-0.115891 -0.0658844 0.0871743" quat="1 0 0 0" type="mesh" contype="1" conaffinity="0" group="1" density="0" rgba="0.0281746 0.0281746 0.0281746 1" mesh="battery_pin_right"/>
    <geom name="chassis_2" pos="-0.0059039 0.0004154 0.0874455" quat="1 0 0 0" type="mesh" contype="1" conaffinity="0" group="1" density="0" rgba="0.0981132 0.0981132 0.0981132 1" mesh="chassis"/>
    <geom name="controller_2" pos="-0.114229 -0.0006716 0.087325" quat="1 0 0 0" type="mesh" contype="1" conaffinity="0" group="1" density="0" rgba="0.0281746 0.0281746 0.0281746 1" mesh="controller"/>
    <geom name="controller_cover_2" pos="-0.0787757 -0.002522 0.106733" quat="1 0 0 0" type="mesh" contype="1" conaffinity="0" group="1" density="0" rgba="0.254832 0.254832 0.254832 0.3" mesh="controller_cover"/>
    <geom name="front_hit_sensor_2" pos="0.156999 -0.0004276 0.0779362" quat="1 0 0 0" type="mesh" contype="1" conaffinity="0" group="1" density="0" rgba="0.169785 0.169785 0.169785 1" mesh="hit_sensor"/>
    <geom name="front_led_2" pos="0.165741 -0.0017117 0.0779737" quat="1 0 0 0" type="mesh" contype="1" conaffinity="0" group="1" density="0" rgba="0 0.777358 0.777358 1" mesh="led"/>
    <geom name="left_hit_sensor_2" pos="-0.0024413 0.0886932 0.0644841" quat="0.707107 0 0 0.707107" type="mesh" contype="1" conaffinity="0" group="1" density="0" rgba="0.169785 0.169785 0.169785 1" mesh="hit_sensor"/>
    <geom name="left_led_2" pos="-0.0011572 0.097436 0.0645216" quat="0.707107 0 0 0.707107" type="mesh" contype="1" conaffinity="0" group="1" density="0" rgba="0 0.777358 0.777358 1" mesh="led"/>
    <geom name="rear_hit_sensor_2" pos="-0.158183 -0.0027864 0.0650168" quat="0 0 0 1" type="mesh" contype="1" conaffinity="0" group="1" density="0" rgba="0.169785 0.169785 0.169785 1" mesh="hit_sensor"/>
    <geom name="rear_led_2" pos="-0.166926 -0.0015023 0.0650543" quat="0 0 0 1" type="mesh" contype="1" conaffinity="0" group="1" density="0" rgba="0 0.777358 0.777358 1" mesh="led"/>
    <geom name="right_hit_sensor_2" pos="-0.0024413 -0.0886932 0.0644841" quat="0.707107 0 0 -0.707107" type="mesh" contype="1" conaffinity="0" group="1" density="0" rgba="0.169785 0.169785 0.169785 1" mesh="hit_sensor"/>
    <geom name="right_led_2" pos="-0.0037254 -0.097436 0.0645216" quat="0.707107 0 0 -0.707107" type="mesh" contype="1" conaffinity="0" group="1" density="0" rgba="0 0.777358 0.777358 1" mesh="led"/>
    <geom name="gimbal_base_2" pos="-0.002 0 0.118" quat="1 0 0 0" type="mesh" contype="1" conaffinity="0" group="1" density="0" rgba="0.12595 0.12595 0.12595 1" mesh="gimbal_base"/>
    <geom name="gimbal_2" pos="-0.00202 -0.001 0.15169" quat="1 0 0 0" type="mesh" contype="1" conaffinity="0" group="1" density="0" rgba="0.12595 0.12595 0.12595 1" mesh="gimbal"/>
    <geom name="gimbal_left_armor_2" pos="-0.00672 0.06418 0.18922" quat="1 0 0 0" type="mesh" contype="1" conaffinity="0" group="1" density="0" rgba="0.06401 0.06401 0.06401 1" mesh="gimbal_left_armor"/>
    <geom name="gimbal_right_armor_2" pos="-0.00727 -0.06277 0.19114" quat="1 0 0 0" type="mesh" contype="1" conaffinity="0" group="1" density="0" rgba="0.06401 0.06401 0.06401 1" mesh="gimbal_right_armor"/>
    <geom name="gimbal_side_2" pos="-0.00227 0.00034 0.20555" quat="1 0 0 0" type="mesh" contype="1" conaffinity="0" group="1" density="0" rgba="0.01758 0.01758 0.01758 1" mesh="gimbal_side"/>
    <geom name="blaster_bug_2" pos="-0.00198 -0.03893 0.21319" quat="1 0 0 0" type="mesh" contype="1" conaffinity="0" group="1" density="0" rgba="0.06401 0.06401 0.06401 1" mesh="blaster_bug"/>
    <geom name="blaster_gun_2" pos="0.03669 0.0036 0.19484" quat="1 0 0 0" type="mesh" contype="1" conaffinity="0" group="1" density="0" rgba="0.06401 0.06401 0.06401 1" mesh="blaster_gun"/>
    <geom name="blaster_magazin_2" pos="-0.02258 0.00035 0.23421" quat="1 0 0 0" type="mesh" contype="1" conaffinity="0" group="1" density="0" rgba="0.76578 0.76578 0.76578 1" mesh="blaster_magazin"/>
    <geom name="blaster_top_2" pos="-0.00087 0.00116 0.22258" quat="1 0 0 0" type="mesh" contype="1" conaffinity="0" group="1" density="0" rgba="0.47861 0.47861 0.47861 1" mesh="blaster_top"/>
    <geom name="speaker_2" pos="-0.01528 0.00725 0.14438" quat="1 0 0 0" type="mesh" contype="1" conaffinity="0" group="1" density="0" mesh="speaker"/>
    <geom name="camera_2" pos="0.0701244 0.00034 0.236979" quat="0.996195 0 -0.0871539 0" type="mesh" contype="1" conaffinity="0" group="1" density="0" rgba="0.0281746 0.028 0.0281746 1" mesh="camera"/>
    <geom name="intelligent_controller_2" pos="-0.02927 0.00034 0.266027" quat="1 0 0 0" type="mesh" contype="1" conaffinity="0" group="1" density="0" rgba="0.8 0.8 0.8 1" mesh="intelligent_controller"/>
    <geom name="wifi_antenna_left_2" pos="-0.0439805 0.0348187 0.278837" quat="1 0 0 0" type="mesh" contype="1" conaffinity="0" group="1" density="0" rgba="0.8 0.8 0.8 1" mesh="wifi_antenna_left"/>
    <geom name="wifi_antenna_right_2" pos="-0.0439825 -0.0347998 0.27975" quat="1 0 0 0" type="mesh" contype="1" conaffinity="0" group="1" density="0" rgba="0.8 0.8 0.8 1" mesh="wifi_antenna_right"/>
    <geom name="top_2" size="0.0544865 0.0295514 0.0114575" pos="-0.0061042 0.0003198 0.264166" type="box" rgba="0.8 0.8 0.8 1" contype="1" conaffinity="0" group="1"/>
    <geom name="gimbal_left_led_2" pos="-0.02631 0.07079 0.22176" quat="1 0 0 0" type="mesh" contype="1" conaffinity="0" group="1" density="0" rgba="0.78118 0.78118 0.78118 1" mesh="gimbal_left_led"/>
    <geom name="gimbal_left_led0_2" pos="-0.02533 0.07079 0.18827" quat="1 0 0 0" type="mesh" contype="1" conaffinity="0" group="1" density="0" rgba="0.78118 0.78118 0.78118 1" mesh="gimbal_left_led_0"/>
    <geom name="gimbal_left_led1_2" pos="-0.01005 0.07079 0.17784" quat="1 0 0 0" type="mesh" contype="1" conaffinity="0" group="1" density="0" rgba="0.78118 0.78118 0.78118 1" mesh="gimbal_left_led_1"/>
    <geom name="gimbal_left_led2_2" pos="0.00859 0.07079 0.17874" quat="1 0 0 0" type="mesh" contype="1" conaffinity="0" group="1" density="0" rgba="0.78118 0.78118 0.78118 1" mesh="gimbal_left_led_2"/>
    <geom name="gimbal_left_led3_2" pos="0.0226 0.07079 0.1906" quat="1 0 0 0" type="mesh" contype="1" conaffinity="0" group="1" density="0" rgba="0.78118 0.78118 0.78118 1" mesh="gimbal_left_led_3"/>
    <geom name="gimbal_left_led4_2" pos="0.02121 0.07075 0.22233" quat="1 0 0 0" type="mesh" contype="1" conaffinity="0" group="1" density="0" rgba="0.78118 0.78118 0.78118 1" mesh="gimbal_left_led_4"/>
    <geom name="gimbal_left_led5_2" pos="0.00706 0.07079 0.23264" quat="1 0 0 0" type="mesh" contype="1" conaffinity="0" group="1" density="0" rgba="0.78118 0.78118 0.78118 1" mesh="gimbal_left_led_5"/>
    <geom name="gimbal_left_led6_2" pos="-0.01119 0.0708 0.2327" quat="1 0 0 0" type="mesh" contype="1" conaffinity="0" group="1" density="0" rgba="0.78118 0.78118 0.78118 1" mesh="gimbal_left_led_6"/>
    <geom name="gimbal_left_led7_2" pos="-0.02631 0.07079 0.22176" quat="1 0 0 0" type="mesh" contype="1" conaffinity="0" group="1" density="0" rgba="0.78118 0.78118 0.78118 1" mesh="gimbal_left_led_7"/>
    <geom name="gimbal_right_led0_2" pos="-0.02532 -0.0695 0.18827" quat="1 0 0 0" type="mesh" contype="1" conaffinity="0" group="1" density="0" rgba="0.78118 0.78118 0.78118 1" mesh="gimbal_right_led_0"/>
    <geom name="gimbal_right_led1_2" pos="-0.01005 -0.06952 0.17783" quat="1 0 0 0" type="mesh" contype="1" conaffinity="0" group="1" density="0" rgba="0.78118 0.78118 0.78118 1" mesh="gimbal_right_led_1"/>
    <geom name="gimbal_right_led2_2" pos="0.00859 -0.06952 0.17874" quat="1 0 0 0" type="mesh" contype="1" conaffinity="0" group="1" density="0" rgba="0.78118 0.78118 0.78118 1" mesh="gimbal_right_led_2"/>
    <geom name="gimbal_right_led3_2" pos="0.0226 -0.06952 0.1906" type="mesh" contype="1" conaffinity="0" group="1" density="0" rgba="0.78118 0.78118 0.78118 1" mesh="gimbal_right_led_3"/>
    <geom name="gimbal_right_led4_2" pos="0.02122 -0.06924 0.22232" quat="1 0 0 0" type="mesh" contype="1" conaffinity="0" group="1" density="0" rgba="0.78118 0.78118 0.78118 1" mesh="gimbal_right_led_4"/>
    <geom name="gimbal_right_led5_2" pos="0.00706 -0.06933 0.2327" quat="1 0 0 0" type="mesh" contype="1" conaffinity="0" group="1" density="0" rgba="0.78118 0.78118 0.78118 1" mesh="gimbal_right_led_5"/>
    <geom name="gimbal_right_led6_2" pos="-0.01125 -0.06933 0.23267" quat="1 0 0 0" type="mesh" contype="1" conaffinity="0" group="1" density="0" rgba="0.78118 0.78118 0.78118 1" mesh="gimbal_right_led_6"/>
    <geom name="gimbal_right_led7_2" pos="-0.02631 -0.06933 0.22176" type="mesh" contype="1" conaffinity="0" group="1" density="0" rgba="0.78118 0.78118 0.78118 1" mesh="gimbal_right_led7"/>
    

    <!-- <joint armature="0" axis="1 0 0" damping="0" limited="false" name="rm_x_2" pos="0 0 0" stiffness="0" type="slide"/>
    <joint armature="0" axis="0 1 0" damping="0" limited="false" name="rm_y_2" pos="0 0 0" stiffness="0" type="slide"/>
    <joint armature="0" axis="0 0 1" damping="0" limited="false" name="rm_z_2" pos="0 0 0" stiffness="0" type="slide"/>
    <joint armature="0" axis="0 0 1" damping="0" limited="false" name="rot_z_2" pos="0 0 0" stiffness="0" type="hinge"/> -->
    <body name="rm_front_left_wheel_link_2" pos="0.1 0.1 0.05" gravcomp="1">
      <inertial pos="-0.0002104 5.31e-05 -0.0004148" mass="0.162" diaginertia="0.0002 0.00012 0.00012"/>
      <joint name="rm_front_left_wheel_joint_2" pos="0 0 0" axis="0 1 0"/>
      <geom name="front_left_wheel_bolt_2" size="0.007 0.0005" pos="0 0.0145 0" quat="0.707107 0.707107 0 0" type="cylinder" contype="1" conaffinity="0" group="1" density="0" rgba="0.45 0.15 0 1"/>
      <geom name="front_left_wheel_2" type="mesh" contype="0" conaffinity="0" group="1" density="0" rgba="0.273909 0.273909 0.273909 1" mesh="wheel" friction="0 0 0"/>
    </body>
    <body name="rm_front_right_wheel_link_2" pos="0.1 -0.1 0.05" gravcomp="1">
      <inertial pos="-0.0002104 5.31e-05 -0.0004148" mass="0.162" diaginertia="0.0002 0.00012 0.00012"/>
      <joint name="rm_front_right_wheel_joint_2" pos="0 0 0" axis="0 1 0"/>
      <geom name="front_right_wheel_bolt_2" size="0.007 0.0005" pos="0 -0.0145 0" quat="0.707107 0.707107 0 0" type="cylinder" contype="1" conaffinity="0" group="1" density="0" rgba="0.45 0.15 0 1"/>
      <geom name="front_right_wheel_2" type="mesh" contype="1" conaffinity="0" group="1" density="0" rgba="0.273909 0.273909 0.273909 1" mesh="wheel_mirror" friction="0 0 0"/>
    </body>
    <body name="rm_rear_left_wheel_link_2" pos="-0.1 0.1 0.05" gravcomp="1">
      <inertial pos="-0.0002104 5.31e-05 -0.0004148" mass="0.162" diaginertia="0.0002 0.00012 0.00012"/>
      <joint name="rm_rear_left_wheel_joint_2" pos="0 0 0" axis="0 1 0"/>
      <geom name="rear_left_wheel_bolt_2" size="0.007 0.0005" pos="0 0.0145 0" quat="0.707107 0.707107 0 0" type="cylinder" contype="1" conaffinity="0" group="1" density="0" rgba="0.45 0.15 0 1"/>
      <geom name="rear_left_wheel_2"  type="mesh" contype="1" conaffinity="0" group="1" density="0" rgba="0.273909 0.273909 0.273909 1" mesh="wheel_mirror" friction="0 0 0"/>
    </body>
    <body name="rm_rear_right_wheel_link_2" pos="-0.1 -0.1 0.05" gravcomp="1">
      <inertial pos="-0.0002104 5.31e-05 -0.0004148" mass="0.162" diaginertia="0.0002 0.00012 0.00012"/>
      <joint name="rm_rear_right_wheel_joint_2" pos="0 0 0" axis="0 1 0"/>
      <geom name="rear_right_wheel_bolt_2" size="0.007 0.0005" pos="0 -0.0145 0" quat="0.707107 0.707107 0 0" type="cylinder" contype="1" conaffinity="0" group="1" density="0" rgba="0.45 0.15 0 1"/>
      <geom name="rear_right_wheel_2" type="mesh" contype="1" conaffinity="0" group="1" density="0" rgba="0.273909 0.273909 0.273909 1" mesh="wheel" friction="0 0 0"/>
    <!-- <light name="tracking_rm_light" pos="0 0 20" dir="0 0 -1" diffuse="10 10 10"/> -->
    <!-- <camera name="rm_track_cam_2" pos="0 0 5" quat="0 0 0 -1"/> -->
    </body>
  </body>

    </worldbody>

  <actuator>
    <motor name="apollo_rear_left_wheel_joint" joint="apollo_rear_left_wheel_joint" ctrllimited="true" ctrlrange="-100 100" forcelimited="true" forcerange="-100 100"/>
    <motor name="apollo_rear_right_wheel_joint" joint="apollo_rear_right_wheel_joint" gear="-1" ctrllimited="true" ctrlrange="-100 100" forcelimited="true" forcerange="-100 100"/>
    <position name="left_steering_joint" joint= "left_steering_joint" kp="1000" kv='10' ctrllimited="true" forcelimited="true" forcerange="-200 200" ctrlrange="-0.5 0.5"/>
    <position name="right_steering_joint" joint= "right_steering_joint"  kp="1000" kv='10' ctrllimited="true" forcelimited="true" forcerange="-200 200" ctrlrange="-0.5 0.5"/>
    <!-- <motor name="handle_joint"  joint="handle_joint" ctrllimited="false"  forcelimited="true" forcerange="-500 500"/>
    <motor name="plane_joint"  joint="plane_joint"   ctrllimited="false" forcelimited="true" forcerange="-500 500"/> -->
    <position name="handle_joint"  joint="handle_joint" ctrllimited="true" kp="500" kv='10' ctrlrange="-0.63 0"  forcelimited="true" forcerange="-500 500"/>
    <position name="plane_joint"  joint="plane_joint"   ctrllimited="true" kp="500" kv='10' ctrlrange="0 1.6" forcelimited="true" forcerange="-500 500"/>
    
    <!-- <velocity name="rm_front_left_wheel_joint" joint= "rm_front_left_wheel_joint" kv='10'/>
    <velocity name="rm_front_right_wheel_joint" joint= "rm_front_right_wheel_joint"  kv='10'/>
    <velocity name="rm_rear_left_wheel_joint" joint= "rm_rear_left_wheel_joint"  kv='10'/>
    <velocity name="rm_rear_right_wheel_joint" joint= "rm_rear_right_wheel_joint"  kv='10'/>

    <velocity name="rm_front_left_wheel_joint_2" joint= "rm_front_left_wheel_joint_2" kv='10'/>
    <velocity name="rm_front_right_wheel_joint_2" joint= "rm_front_right_wheel_joint_2" kv='10'/>
    <velocity name="rm_rear_left_wheel_joint_2" joint= "rm_rear_left_wheel_joint_2" kv='10'/>
    <velocity name="rm_rear_right_wheel_joint_2" joint= "rm_rear_right_wheel_joint_2" kv='10'/> -->
    <!-- <position name="rm_x"  joint="rm_y" ctrllimited="false" gear='-1' kp="100" kv='1'  forcelimited="true" forcerange="-500 500"/>
    <position name="rm_y"  joint="rm_x" ctrllimited="false" kp="100" kv='1'  forcelimited="true" forcerange="-500 500"/>
    <position name="rm_z"  joint="rm_z" ctrllimited="false" kp="10" kv='1'  forcelimited="true" forcerange="-500 500"/>
    <position name="rot_z"  joint="rot_z" ctrllimited="false" kp="10" kv='1'  forcelimited="true" forcerange="-500 500"/> 
    <position name="rm_x_2"  joint="rm_y_2" ctrllimited="false" gear='-1' kp="100" kv='1'  forcelimited="true" forcerange="-500 500"/>
    <position name="rm_y_2"  joint="rm_x_2" ctrllimited="false" kp="100" kv='1'  forcelimited="true" forcerange="-500 500"/>
    <position name="rm_z_2"  joint="rm_z_2" ctrllimited="false" kp="10" kv='1'  forcelimited="true" forcerange="-500 500"/>
    <position name="rot_z_2"  joint="rot_z_2" ctrllimited="false" kp="10" kv='1'  forcelimited="true" forcerange="-500 500"/> -->
  </actuator>


</mujoco>
